<?xml version="1.0"?>
<robot name="mythird">

    <joint name="base_to_sub1" type="revolute">
        <parent link="base_link"/>
        <child link="sub_link1"/>
        <axis xyz="1 0 0"/>
        <limit effort="10" upper="0" lower="10" velocity="1"/>
        <origin rpy="0 0.1 0" xyz="0 0 1.2" />
    </joint>
      <joint name="base_to_sub2" type="revolute">
        <parent link="base_link"/>
        <child link="sub_link2"/>
        <axis xyz="1 2 0"/>
        <limit effort="10" upper="0" lower="10" velocity="1"/>
        <origin rpy="0 0.1 0" xyz="-0.3 0 -1.4" />
    </joint>
    <joint name="base_to_sub3" type="revolute">
        <parent link="base_link"/>
        <child link="sub_link3"/>
        <axis xyz="1 0 0"/>
        <limit effort="10" upper="0" lower="10" velocity="1"/>
        <origin rpy="0 0.3 0" xyz="-0.4 0 -0.9" />
    </joint>
    <joint name="base_to_sub4" type="revolute">
        <parent link="base_link"/>
        <child link="sub_link4"/>
        <axis xyz="1 0 0"/>
        <limit effort="10" upper="0" lower="10" velocity="1"/>
        <origin rpy="0 0 0" xyz="-1.2 0 -0.4" />
    </joint>
      <joint name="base_to_sub5" type="revolute">
        <parent link="base_link"/>
        <child link="sub_link5"/>
        <axis xyz="1 0 0"/>
        <limit effort="10" upper="0" lower="10" velocity="1"/>
        <origin rpy="0 0 0" xyz="-0.2 0 -1.2" />
    </joint>

    <link name="base_link">
        <visual>
            <geometry>
                <sphere radius="0.5"/>
            </geometry>
        </visual>
        <collision>
             <geometry>
                <sphere radius="0.5"/>
            </geometry>
        </collision>
        <inertial>
            <mass value="1.0"/>
            <inertia ixx="0.0005" iyy="0.0005" izz="0.0005"
            ixy="0" ixz="0" iyz="0"/>
        </inertial>
    </link>
    <link name="sub_link1">
        <visual>
            <geometry>
                <cylinder length="3" radius="0.1"/>
            </geometry>
        </visual>
        <collision>
             <geometry>
                <cylinder length="3" radius="0.1"/>
            </geometry>
        </collision>
        <inertial>
            <mass value="0.5"/>
            <inertia ixx="0.0003" iyy="0.0003" izz="0.0003"
            ixy="0" ixz="0" iyz="0"/>
        </inertial>
    </link>
    <link name="sub_link2">
        <visual>
            <geometry>
                <cylinder length="3" radius="0.1"/>
            </geometry>
        </visual>
        <collision>
             <geometry>
                <cylinder length="3" radius="0.1"/>
            </geometry>
        </collision>
        <inertial>
            <mass value="0.5"/>
            <inertia ixx="0.0003" iyy="0.0003" izz="0.0003"
            ixy="0" ixz="0" iyz="0"/>
        </inertial>
    </link>
    <link name="sub_link3">
        <visual>
            <geometry>
                <cylinder length="3" radius="0.1"/>
            </geometry>
        </visual>
        <collision>
             <geometry>
                <cylinder length="3" radius="0.1"/>
            </geometry>
        </collision>
        <inertial>
            <mass value="0.5"/>
            <inertia ixx="0.0003" iyy="0.0003" izz="0.0003"
            ixy="0" ixz="0" iyz="0"/>
        </inertial>
    </link>
    <link name="sub_link4">
        <visual>
            <geometry>
                <cylinder length="3" radius="0.1"/>
            </geometry>
        </visual>
        <collision>
             <geometry>
                <cylinder length="3" radius="0.1"/>
            </geometry>
        </collision>
        <inertial>
            <mass value="0.5"/>
            <inertia ixx="0.0003" iyy="0.0003" izz="0.0003"
            ixy="0" ixz="0" iyz="0"/>
        </inertial>
    </link>
    <link name="sub_link5">
        <visual>
            <geometry>
                <cylinder length="3" radius="0.1"/>
            </geometry>
        </visual>
        <collision>
             <geometry>
                <cylinder length="3" radius="0.1"/>
            </geometry>
        </collision>
        <inertial>
            <mass value="0.5"/>
            <inertia ixx="0.0003" iyy="0.0003" izz="0.0003"
            ixy="0" ixz="0" iyz="0"/>
        </inertial>
    </link>
</robot>
